### Что такое `.then().catch()` в контексте `fetch`?

`fetch` возвращает `Promise`, который позволяет использовать методы `.then()` и `.catch()` для обработки асинхронных операций. 

Конструкция `.then().catch()` — это способ построить цепочку обработки результата и ошибок:

- **`.then(onFulfilled, [onRejected])`**: Первый аргумент обрабатывает успешное выполнение (`fulfilled`), второй (необязательный) — ошибки (`rejected`). Второй аргумент редко используется, так как `.catch()` удобнее.
- **`.catch(onRejected)`**: Перехватывает ошибки, возникшие в цепочке `Promise`, будь то сетевые ошибки, HTTP-ошибки (при ручной проверке `response.ok`) или исключения в `.then()`.

### Роль `.catch()` в цепочке:

`.catch()` — это метод `Promise`, который вызывается, если:
- Предыдущий `Promise` в цепочке отклонён (`rejected`) через `reject(error)` или `throw`.
- Произошла сетевая ошибка (например, сервер недоступен).
- В `.then()` выброшено исключение (например, `throw new Error()`).

**Особенности `.catch()`**:

- Перехватывает ошибки из **всех** предыдущих `.then()` в цепочке.
- Возвращает новый `Promise`, что позволяет продолжить цепочку после обработки ошибки.
- Если ошибка не обработана, возникает `unhandled promise rejection`, что в Node.js может привести к крашу, а в браузере — к предупреждению.
- `.catch()` можно размещать в любом месте цепочки, но обычно его ставят в конце, чтобы поймать все возможные ошибки.

### Почему `.catch()` важен для `fetch`?

`fetch` имеет особенность: он **не отклоняет `Promise` при HTTP-ошибках** (например, 404, 500). `Promise` от `fetch` завершается с состоянием `rejected` только при сетевых ошибках (например, отсутствие интернета). Поэтому в `.then()` нужно вручную проверять `response.ok` и выбрасывать ошибку, чтобы `.catch()` её поймал.

### Примеры использования `.then().catch()` с `fetch`:

#### 1. Простой `fetch` с обработкой ошибок

```javascript
fetch('https://jsonplaceholder.typicode.com/posts/1')
  .then(response => {
    if (!response.ok) {
      throw new Error(`HTTP ошибка: ${response.status} ${response.statusText}`);
    }
    return response.json();
  })
  .then(data => {
    console.log('Данные:', data);
    return data;
  })
  .catch(error => {
    console.error('Ошибка:', error.message);
    // Можно вернуть значение по умолчанию, чтобы продолжить цепочку
    return { error: true, message: error.message };
  })
  .then(result => {
    console.log('Результат после catch:', result);
  });
```

**Объяснение**:
- В первом `.then()` проверяем `response.ok`. Если `false` (например, 404), выбрасываем ошибку.
- Второй `.then()` обрабатывает данные, если запрос успешен.
- `.catch()` ловит:
  - Сетевые ошибки (например, сервер недоступен).
  - HTTP-ошибки, выброшенные через `throw` в первом `.then()`.
  - Ошибки парсинга JSON, если `response.json()` не удалось.
- `.catch()` возвращает объект с ошибкой, и цепочка продолжается.

#### 2. Обработка разных типов ошибок

```javascript
fetch('https://invalid-url.example.com') // Несуществующий домен
  .then(response => {
    if (!response.ok) {
      throw new Error(`HTTP ошибка: ${response.status}`);
    }
    return response.json();
  })
  .then(data => {
    if (!data.title) {
      throw new Error('Данные не содержат title');
    }
    console.log('Заголовок:', data.title);
  })
  .catch(error => {
    if (error.message.includes('HTTP ошибка')) {
      console.error('Проблема с HTTP:', error.message);
    } else if (error.message.includes('Failed to fetch')) {
      console.error('Сетевая ошибка (сервер недоступен):', error.message);
    } else {
      console.error('Другая ошибка:', error.message);
    }
  });
```

**Объяснение**:
- `.catch()` обрабатывает:
  - Сетевые ошибки (`Failed to fetch` при недоступном сервере).
  - HTTP-ошибки (например, 404, выброшенные вручную).
  - Логические ошибки (например, отсутствие `title` в данных).
- Можно анализировать `error.message` для классификации ошибок.

#### 3. Множественные `.catch()` в цепочке
Можно использовать несколько `.catch()` для обработки ошибок на разных этапах.

```javascript
fetch('https://jsonplaceholder.typicode.com/posts/1')
  .then(response => {
    if (!response.ok) {
      throw new Error(`HTTP ошибка: ${response.status}`);
    }
    return response.json();
  })
  .catch(error => {
    console.error('Ошибка на этапе запроса:', error.message);
    return null; // Продолжаем цепочку с null
  })
  .then(data => {
    if (!data) {
      throw new Error('Нет данных');
    }
    console.log('Данные:', data);
    return data.title.toUpperCase();
  })
  .catch(error => {
    console.error('Ошибка на этапе обработки данных:', error.message);
    return 'ЗАГОЛОВОК ПО УМОЛЧАНИЮ';
  })
  .then(finalResult => {
    console.log('Финальный результат:', finalResult);
  });
```

**Объяснение**:
- Первый `.catch()` обрабатывает ошибки `fetch` (сетевые или HTTP).
- Второй `.catch()` ловит ошибки обработки данных (например, если `data` — `null`).
- Каждый `.catch()` возвращает значение, чтобы цепочка продолжилась.
- Это позволяет разделить обработку ошибок для разных этапов.

#### 4. Комбинация с `Promise.all` и `.catch()`

```javascript
Promise.all([
  fetch('https://jsonplaceholder.typicode.com/posts/1').then(res => {
    if (!res.ok) throw new Error('Ошибка поста');
    return res.json();
  }),
  fetch('https://invalid-url.example.com').then(res => {
    if (!res.ok) throw new Error('Ошибка пользователя');
    return res.json();
  }),
])
  .then(([post, user]) => {
    console.log('Пост:', post.title, 'Пользователь:', user.name);
  })
  .catch(error => {
    console.error('Ошибка в одном из запросов:', error.message);
    return { post: null, user: null }; // Восстановление цепочки
  })
  .then(result => {
    console.log('Результат:', result);
  });
```

**Объяснение**:
- `Promise.all` отклоняется, если хотя бы один `Promise` в массиве `rejected`.
- `.catch()` ловит первую ошибку (в данном случае сетевую ошибку от `invalid-url`).
- Возвращаем значение по умолчанию, чтобы цепочка продолжилась.

#### 5. `.catch()` с таймаутом
Добавим таймаут к `fetch` с помощью `AbortController`.

```javascript
async function fetchWithTimeout(url, timeout = 5000) {
  const controller = new AbortController();
  const timeoutId = setTimeout(() => controller.abort(), timeout);

  return fetch(url, { signal: controller.signal })
    .then(response => {
      clearTimeout(timeoutId);
      if (!response.ok) {
        throw new Error(`HTTP ошибка: ${response.status}`);
      }
      return response.json();
    })
    .catch(error => {
      if (error.name === 'AbortError') {
        throw new Error('Запрос превысил время ожидания');
      }
      throw error; // Пробрасываем другие ошибки
    });
}

fetchWithTimeout('https://jsonplaceholder.typicode.com/posts/1', 1000)
  .then(data => console.log('Данные:', data))
  .catch(error => console.error('Ошибка:', error.message));
```

**Объяснение**:
- `AbortController` прерывает запрос, если он превышает таймаут.
- `.catch()` различает `AbortError` (таймаут) и другие ошибки.
- Ошибка пробрасывается дальше для обработки в следующей цепочке.

### Подробности о `.catch()`:

1. **Что ловит `.catch()`?**
   - **Сетевые ошибки**: Например, `Failed to fetch` при отсутствии интернета или неверном URL.
   - **HTTP-ошибки**: Только если вы вручную выбрасываете `throw` при проверке `response.ok`.
   - **Ошибки парсинга**: Например, если `response.json()` не может разобрать ответ.
   - **Ошибки в `.then()`**: Любые исключения (`throw`) в обработчиках.
   - **Ошибки асинхронных операций**: Если в `.then()` возвращается `Promise`, который отклоняется.

2. **Пропагация ошибок**:
   - Ошибка, возникшая в любом `.then()`, передаётся вниз по цепочке, пока не будет поймана `.catch()`.
   - Если `.catch()` возвращает значение, новый `Promise` становится `fulfilled`, и цепочка продолжается.

3. **Множественные `.catch()`**:
   - Можно ставить `.catch()` после каждого `.then()` для локальной обработки.
   - Последний `.catch()` в цепочке обычно используется как "глобальный" обработчик.

4. **Возврат из `.catch()`**:
   - Если `.catch()` возвращает значение, цепочка продолжается как `fulfilled`.
   - Если `.catch()` выбрасывает ошибку (`throw`), следующий `.catch()` её перехватит.

5. **Сравнение с `.then(null, onRejected)`**:
   - `.then(null, onRejected)` эквивалентно `.catch(onRejected)`, но `.catch()` читается лучше.
   - Использование `.then(null, onRejected)` редко, так как менее интуитивно.

### Лучшие практики для `.catch()` с `fetch`:

1. **Всегда добавляйте `.catch()`**:
   Без `.catch()` необработанные ошибки вызовут `unhandled promise rejection`.

   ```javascript
   fetch(url).then(res => res.json()).catch(error => console.error(error));
   ```

2. **Проверяйте `response.ok`**:
   `fetch` не отклоняет `Promise` при HTTP-ошибках, поэтому выбрасывайте ошибку вручную:
   
   ```javascript
   .then(response => {
     if (!response.ok) throw new Error(`HTTP ошибка: ${response.status}`);
     return response.json();
   })
   ```

3. **Классифицируйте ошибки**:
   Различайте типы ошибок в `.catch()` для точной обработки:
   
   ```javascript
   .catch(error => {
     if (error.name === 'TypeError') {
       console.error('Сетевая ошибка:', error);
     } else if (error.message.includes('HTTP')) {
       console.error('Ошибка сервера:', error);
     } else {
       console.error('Неизвестная ошибка:', error);
     }
   });
   ```

4. **Восстанавливайте цепочку**:
   Возвращайте значение по умолчанию из `.catch()`, чтобы избежать прерывания:
   
   ```javascript
   .catch(error => {
     console.error(error);
     return null; // Продолжаем с null
   });
   ```

5. **Избегайте дублирования**:
   Вместо нескольких `.catch()` для похожих ошибок используйте один в конце цепочки.

6. **Комбинируйте с `async/await`**:
   Для простоты используйте `try/catch` вместо `.catch()`:
   
   ```javascript
   async function fetchData() {
     try {
       const response = await fetch(url);
       if (!response.ok) throw new Error(`HTTP ошибка: ${response.status}`);
       return await response.json();
     } catch (error) {
       console.error('Ошибка:', error.message);
       return null;
     }
   }
   ```

7. **Логируйте ошибки**:
   Всегда выводите ошибки в `.catch()` для отладки. Можно отправлять их в систему мониторинга (например, Sentry).

8. **Тестирование**:
   В тестах проверяйте ошибки с помощью `.rejects`:
   
   ```javascript
   test('fetch fails', async () => {
     await expect(fetch('invalid-url').then(res => res.json())).rejects.toThrow('Failed to fetch');
   });
   ```

### Проблемы и антипаттерны:

1. **Пропуск `.catch()`**:
   Без `.catch()` ошибки могут остаться незамеченными, что приведёт к предупреждениям или сбоям.

2. **Неправильная проверка `response.ok`**:
   Забывая проверять `response.ok`, вы можете обработать 404 или 500 как успех.

3. **Избыточные `.catch()`**:
   Множественные `.catch()` для одной и той же ошибки усложняют код. Используйте один глобальный.

4. **Игнорирование возврата из `.catch()`**:
   Если не вернуть значение, следующий `.then()` получит `undefined`.

### Заключение:

`.catch()` в цепочке `.then().catch()` с `fetch` — это критически важный инструмент для обработки ошибок, включая сетевые сбои, HTTP-ошибки (при ручном `throw`) и исключения в обработчиках. Примеры выше показывают, как использовать `.catch()` для разных сценариев: от простых запросов до сложных цепочек с множественными ошибками. Важно всегда проверять `response.ok`, классифицировать ошибки и возвращать значения из `.catch()` для продолжения цепочки.